Workbook

Sheet Precios de venta
A1: Marca | B1: Referencia | C1: Producto en la tienda | D1: Costo proveedor (USD) | E1: Costo puesto en depósito | F1: Costo + envío al cliente | G1: Precio mínimo (ganancia ≥ piso) | H1: Precio objetivo | I1: Precio de la calle (mercado) | J1: PRECIO DE VENTA 1 filtro | K1: Ganancia por filtro (USD) | L1: Margen % | M1: Precio paquete de 2 | N1: Ganancia paquete (USD) | O1: Veredicto | P1: Precios vistos en el mercado | Q1: Fuente | R1: Cartón | S1: Nota del proveedor
A2: Samsung | B2: DA29-00003F / HA-FIN1 | D2: 19 | E2: =D2*(1+Supuestos!$B$4) | F2: =E2+Supuestos!$B$5 | G2: =ROUNDUP((F2+Supuestos!$B$3+Supuestos!$B$9)/(1-Supuestos!$B$2),0)-0.01 | H2: =ROUNDUP(MAX((F2+Supuestos!$B$3)/(1-Supuestos!$B$2-Supuestos!$B$8),(F2+Supuestos!$B$3+Supuestos!$B$7)/(1-Supuestos!$B$2)),0)-0.01 | J2: 36.99 | K2: =J2-J2*Supuestos!$B$2-Supuestos!$B$3-F2 | L2: =K2/J2 | M2: =ROUNDUP(MAX(2*J2*0.92,(2*E2+Supuestos!$B$6+Supuestos!$B$3+8)/(1-Supuestos!$B$2)),0)-0.01 | N2: =M2-M2*Supuestos!$B$2-Supuestos!$B$3-2*E2-Supuestos!$B$6 | O2: Sin precio de mercado: precio objetivo | P2: Sin datos de mercado | R2: 30
A3: Samsung | B3: DA29-00003G / HAF-CU1 / HAF-FIN2 | C3: sam-cu1-o | D3: 24.5 | E3: =D3*(1+Supuestos!$B$4) | F3: =E3+Supuestos!$B$5 | G3: =ROUNDUP((F3+Supuestos!$B$3+Supuestos!$B$9)/(1-Supuestos!$B$2),0)-0.01 | H3: =ROUNDUP(MAX((F3+Supuestos!$B$3)/(1-Supuestos!$B$2-Supuestos!$B$8),(F3+Supuestos!$B$3+Supuestos!$B$7)/(1-Supuestos!$B$2)),0)-0.01 | J3: 43.99 | K3: =J3-J3*Supuestos!$B$2-Supuestos!$B$3-F3 | L3: =K3/J3 | M3: =ROUNDUP(MAX(2*J3*0.92,(2*E3+Supuestos!$B$6+Supuestos!$B$3+8)/(1-Supuestos!$B$2)),0)-0.01 | N3: =M3-M3*Supuestos!$B$2-Supuestos!$B$3-2*E3-Supuestos!$B$6 | O3: Sin precio de mercado: precio objetivo | P3: Sin datos de mercado | R3: 6
A4: Samsung | B4: DA29-00020B / HAF-CIN | C4: sam-cin-o | D4: 23.5 | E4: =D4*(1+Supuestos!$B$4) | F4: =E4+Supuestos!$B$5 | G4: =ROUNDUP((F4+Supuestos!$B$3+Supuestos!$B$9)/(1-Supuestos!$B$2),0)-0.01 | H4: =ROUNDUP(MAX((F4+Supuestos!$B$3)/(1-Supuestos!$B$2-Supuestos!$B$8),(F4+Supuestos!$B$3+Supuestos!$B$7)/(1-Supuestos!$B$2)),0)-0.01 | I4: 34.99 | O4: No vender suelto: el mercado está casi al precio de costo | P4: Lista 59.99; Allfilters 34.99; eBay desde 18.99 | Q4: allfilters.com, ebay.com | R4: 6
A5: Samsung | B5: DA97-17376B / HAF-QIN | C5: sam-qin-o | D5: 25.5 | E5: =D5*(1+Supuestos!$B$4) | F5: =E5+Supuestos!$B$5 | G5: =ROUNDUP((F5+Supuestos!$B$3+Supuestos!$B$9)/(1-Supuestos!$B$2),0)-0.01 | H5: =ROUNDUP(MAX((F5+Supuestos!$B$3)/(1-Supuestos!$B$2-Supuestos!$B$8),(F5+Supuestos!$B$3+Supuestos!$B$7)/(1-Supuestos!$B$2)),0)-0.01 | I5: 36.99 | O5: No vender suelto: el mercado está casi al precio de costo | P5: Genuino 34–44; Allfilters 36.99; terceros 28.99 por 3 | Q5: allfilters.com, slickdeals.net | R5: 6
A6: Samsung | B6: DA29-10105J / HAF-EX | C6: sam-ex-o | D6: 9.5 | E6: =D6*(1+Supuestos!$B$4) | F6: =E6+Supuestos!$B$5 | G6: =ROUNDUP((F6+Supuestos!$B$3+Supuestos!$B$9)/(1-Supuestos!$B$2),0)-0.01 | H6: =ROUNDUP(MAX((F6+Supuestos!$B$3)/(1-Supuestos!$B$2-Supuestos!$B$8),(F6+Supuestos!$B$3+Supuestos!$B$7)/(1-Supuestos!$B$2)),0)-0.01 | I6: 19 | O6: No vender suelto: el mercado está casi al precio de costo | P6: eBay 15–18 + envío; filtro en línea 4378411RB a 23.49 (Slyman) | Q6: ebay, slymanbros.com | R6: 25
A7: LG | B7: LT1000P | C7: lg-1000-o | D7: 37.75 | E7: =D7*(1+Supuestos!$B$4) | F7: =E7+Supuestos!$B$5 | G7: =ROUNDUP((F7+Supuestos!$B$3+Supuestos!$B$9)/(1-Supuestos!$B$2),0)-0.01 | H7: =ROUNDUP(MAX((F7+Supuestos!$B$3)/(1-Supuestos!$B$2-Supuestos!$B$8),(F7+Supuestos!$B$3+Supuestos!$B$7)/(1-Supuestos!$B$2)),0)-0.01 | I7: 54.99 | J7: 61.99 | K7: =J7-J7*Supuestos!$B$2-Supuestos!$B$3-F7 | L7: =K7/J7 | M7: =ROUNDUP(MAX(2*J7*0.92,(2*E7+Supuestos!$B$6+Supuestos!$B$3+8)/(1-Supuestos!$B$2)),0)-0.01 | N7: =M7-M7*Supuestos!$B$2-Supuestos!$B$3-2*E7-Supuestos!$B$6 | O7: Competitivo | P7: Genuino 54.99; terceros desde 12.95 | Q7: allfilters.com, star-power.com | R7: 36
A8: LG | B8: LT800P | C8: lg-800-o | D8: 36.5 | E8: =D8*(1+Supuestos!$B$4) | F8: =E8+Supuestos!$B$5 | G8: =ROUNDUP((F8+Supuestos!$B$3+Supuestos!$B$9)/(1-Supuestos!$B$2),0)-0.01 | H8: =ROUNDUP(MAX((F8+Supuestos!$B$3)/(1-Supuestos!$B$2-Supuestos!$B$8),(F8+Supuestos!$B$3+Supuestos!$B$7)/(1-Supuestos!$B$2)),0)-0.01 | I8: 54.97 | J8: 59.99 | K8: =J8-J8*Supuestos!$B$2-Supuestos!$B$3-F8 | L8: =K8/J8 | M8: =ROUNDUP(MAX(2*J8*0.92,(2*E8+Supuestos!$B$6+Supuestos!$B$3+8)/(1-Supuestos!$B$2)),0)-0.01 | N8: =M8-M8*Supuestos!$B$2-Supuestos!$B$3-2*E8-Supuestos!$B$6 | O8: Competitivo | P8: PC Richard 54.97 | Q8: pcrichard.com | R8: 49
A9: LG | B9: LT700P | C9: lg-700-o | D9: 36.5 | E9: =D9*(1+Supuestos!$B$4) | F9: =E9+Supuestos!$B$5 | G9: =ROUNDUP((F9+Supuestos!$B$3+Supuestos!$B$9)/(1-Supuestos!$B$2),0)-0.01 | H9: =ROUNDUP(MAX((F9+Supuestos!$B$3)/(1-Supuestos!$B$2-Supuestos!$B$8),(F9+Supuestos!$B$3+Supuestos!$B$7)/(1-Supuestos!$B$2)),0)-0.01 | I9: 49.99 | J9: 54.99 | K9: =J9-J9*Supuestos!$B$2-Supuestos!$B$3-F9 | L9: =K9/J9 | M9: =ROUNDUP(MAX(2*J9*0.92,(2*E9+Supuestos!$B$6+Supuestos!$B$3+8)/(1-Supuestos!$B$2)),0)-0.01 | N9: =M9-M9*Supuestos!$B$2-Supuestos!$B$3-2*E9-Supuestos!$B$6 | O9: Ganancia justa: igualar al mercado | P9: Walmart 50.99; Atomic 44.95; genérico 11–25 | Q9: walmart.com, atomicfilters.com | R9: 36
A10: LG | B10: LT700P without T code | D10: 24.5 | E10: =D10*(1+Supuestos!$B$4) | F10: =E10+Supuestos!$B$5 | G10: =ROUNDUP((F10+Supuestos!$B$3+Supuestos!$B$9)/(1-Supuestos!$B$2),0)-0.01 | H10: =ROUNDUP(MAX((F10+Supuestos!$B$3)/(1-Supuestos!$B$2-Supuestos!$B$8),(F10+Supuestos!$B$3+Supuestos!$B$7)/(1-Supuestos!$B$2)),0)-0.01 | J10: 43.99 | K10: =J10-J10*Supuestos!$B$2-Supuestos!$B$3-F10 | L10: =K10/J10 | M10: =ROUNDUP(MAX(2*J10*0.92,(2*E10+Supuestos!$B$6+Supuestos!$B$3+8)/(1-Supuestos!$B$2)),0)-0.01 | N10: =M10-M10*Supuestos!$B$2-Supuestos!$B$3-2*E10-Supuestos!$B$6 | O10: Sin precio de mercado: precio objetivo | P10: Sin datos de mercado | R10: 36 | S10: Variante sin código T: confirma con el proveedor qué significa antes de venderla como LG.
A11: LG | B11: LT600P | C11: lg-600-o | D11: 36.5 | E11: =D11*(1+Supuestos!$B$4) | F11: =E11+Supuestos!$B$5 | G11: =ROUNDUP((F11+Supuestos!$B$3+Supuestos!$B$9)/(1-Supuestos!$B$2),0)-0.01 | H11: =ROUNDUP(MAX((F11+Supuestos!$B$3)/(1-Supuestos!$B$2-Supuestos!$B$8),(F11+Supuestos!$B$3+Supuestos!$B$7)/(1-Supuestos!$B$2)),0)-0.01 | J11: 59.99 | K11: =J11-J11*Supuestos!$B$2-Supuestos!$B$3-F11 | L11: =K11/J11 | M11: =ROUNDUP(MAX(2*J11*0.92,(2*E11+Supuestos!$B$6+Supuestos!$B$3+8)/(1-Supuestos!$B$2)),0)-0.01 | N11: =M11-M11*Supuestos!$B$2-Supuestos!$B$3-2*E11-Supuestos!$B$6 | O11: Sin precio de mercado: precio objetivo | P11: Sin datos de mercado | R11: 24
A12: LG | B12: LT500P | C12: lg-500-o | D12: 34 | E12: =D12*(1+Supuestos!$B$4) | F12: =E12+Supuestos!$B$5 | G12: =ROUNDUP((F12+Supuestos!$B$3+Supuestos!$B$9)/(1-Supuestos!$B$2),0)-0.01 | H12: =ROUNDUP(MAX((F12+Supuestos!$B$3)/(1-Supuestos!$B$2-Supuestos!$B$8),(F12+Supuestos!$B$3+Supuestos!$B$7)/(1-Supuestos!$B$2)),0)-0.01 | I12: 54.99 | J12: 55.99 | K12: =J12-J12*Supuestos!$B$2-Supuestos!$B$3-F12 | L12: =K12/J12 | M12: =ROUNDUP(MAX(2*J12*0.92,(2*E12+Supuestos!$B$6+Supuestos!$B$3+8)/(1-Supuestos!$B$2)),0)-0.01 | N12: =M12-M12*Supuestos!$B$2-Supuestos!$B$3-2*E12-Supuestos!$B$6 | O12: Competitivo | P12: Allfilters 54.99; terceros 12.95 | Q12: allfilters.com | R12: 36
A13: LG | B13: ADQ73693903 / FSS-002 | C13: lg-ex-o | D13: 9.5 | E13: =D13*(1+Supuestos!$B$4) | F13: =E13+Supuestos!$B$5 | G13: =ROUNDUP((F13+Supuestos!$B$3+Supuestos!$B$9)/(1-Supuestos!$B$2),0)-0.01 | H13: =ROUNDUP(MAX((F13+Supuestos!$B$3)/(1-Supuestos!$B$2-Supuestos!$B$8),(F13+Supuestos!$B$3+Supuestos!$B$7)/(1-Supuestos!$B$2)),0)-0.01 | J13: 25.99 | K13: =J13-J13*Supuestos!$B$2-Supuestos!$B$3-F13 | L13: =K13/J13 | M13: =ROUNDUP(MAX(2*J13*0.92,(2*E13+Supuestos!$B$6+Supuestos!$B$3+8)/(1-Supuestos!$B$2)),0)-0.01 | N13: =M13-M13*Supuestos!$B$2-Supuestos!$B$3-2*E13-Supuestos!$B$6 | O13: Sin precio de mercado: precio objetivo | P13: Sin datos de mercado | R13: 36
A14: LG | B14: LT120F / ADQ73334008 | D14: 18.5 | E14: =D14*(1+Supuestos!$B$4) | F14: =E14+Supuestos!$B$5 | G14: =ROUNDUP((F14+Supuestos!$B$3+Supuestos!$B$9)/(1-Supuestos!$B$2),0)-0.01 | H14: =ROUNDUP(MAX((F14+Supuestos!$B$3)/(1-Supuestos!$B$2-Supuestos!$B$8),(F14+Supuestos!$B$3+Supuestos!$B$7)/(1-Supuestos!$B$2)),0)-0.01 | J14: 35.99 | K14: =J14-J14*Supuestos!$B$2-Supuestos!$B$3-F14 | L14: =K14/J14 | M14: =ROUNDUP(MAX(2*J14*0.92,(2*E14+Supuestos!$B$6+Supuestos!$B$3+8)/(1-Supuestos!$B$2)),0)-0.01 | N14: =M14-M14*Supuestos!$B$2-Supuestos!$B$3-2*E14-Supuestos!$B$6 | O14: Sin precio de mercado: precio objetivo | P14: Sin datos de mercado | R14: 100
A15: GE | B15: MWF | C15: ge-mwf-o | D15: 39 | E15: =D15*(1+Supuestos!$B$4) | F15: =E15+Supuestos!$B$5 | G15: =ROUNDUP((F15+Supuestos!$B$3+Supuestos!$B$9)/(1-Supuestos!$B$2),0)-0.01 | H15: =ROUNDUP(MAX((F15+Supuestos!$B$3)/(1-Supuestos!$B$2-Supuestos!$B$8),(F15+Supuestos!$B$3+Supuestos!$B$7)/(1-Supuestos!$B$2)),0)-0.01 | I15: 45 | O15: No vender suelto: el mercado está casi al precio de costo | P15: Genuino 36–50 (Sears 37.14; Walmart 35.99; Allfilters 45.99) | Q15: searspartsdirect.com, allfilters.com | R15: 6
A16: GE | B16: XWFE | D16: 43 | E16: =D16*(1+Supuestos!$B$4) | F16: =E16+Supuestos!$B$5 | G16: =ROUNDUP((F16+Supuestos!$B$3+Supuestos!$B$9)/(1-Supuestos!$B$2),0)-0.01 | H16: =ROUNDUP(MAX((F16+Supuestos!$B$3)/(1-Supuestos!$B$2-Supuestos!$B$8),(F16+Supuestos!$B$3+Supuestos!$B$7)/(1-Supuestos!$B$2)),0)-0.01 | J16: 68.99 | K16: =J16-J16*Supuestos!$B$2-Supuestos!$B$3-F16 | L16: =K16/J16 | M16: =ROUNDUP(MAX(2*J16*0.92,(2*E16+Supuestos!$B$6+Supuestos!$B$3+8)/(1-Supuestos!$B$2)),0)-0.01 | N16: =M16-M16*Supuestos!$B$2-Supuestos!$B$3-2*E16-Supuestos!$B$6 | O16: Sin precio de mercado: precio objetivo | P16: Solo genéricos a 18–25; sin precio del genuino | Q16: walmart.com | R16: 4 | S16: Tu tienda de Colombia vende el XWF (no es igual al XWFE): confirma cuál vas a vender.
A17: GE | B17: RPWFE | D17: 43 | E17: =D17*(1+Supuestos!$B$4) | F17: =E17+Supuestos!$B$5 | G17: =ROUNDUP((F17+Supuestos!$B$3+Supuestos!$B$9)/(1-Supuestos!$B$2),0)-0.01 | H17: =ROUNDUP(MAX((F17+Supuestos!$B$3)/(1-Supuestos!$B$2-Supuestos!$B$8),(F17+Supuestos!$B$3+Supuestos!$B$7)/(1-Supuestos!$B$2)),0)-0.01 | J17: 68.99 | K17: =J17-J17*Supuestos!$B$2-Supuestos!$B$3-F17 | L17: =K17/J17 | M17: =ROUNDUP(MAX(2*J17*0.92,(2*E17+Supuestos!$B$6+Supuestos!$B$3+8)/(1-Supuestos!$B$2)),0)-0.01 | N17: =M17-M17*Supuestos!$B$2-Supuestos!$B$3-2*E17-Supuestos!$B$6 | O17: Sin precio de mercado: precio objetivo | P17: Sin datos de mercado | R17: 4
A18: GE | B18: AFPWF | D18: 34 | E18: =D18*(1+Supuestos!$B$4) | F18: =E18+Supuestos!$B$5 | G18: =ROUNDUP((F18+Supuestos!$B$3+Supuestos!$B$9)/(1-Supuestos!$B$2),0)-0.01 | H18: =ROUNDUP(MAX((F18+Supuestos!$B$3)/(1-Supuestos!$B$2-Supuestos!$B$8),(F18+Supuestos!$B$3+Supuestos!$B$7)/(1-Supuestos!$B$2)),0)-0.01 | J18: 55.99 | K18: =J18-J18*Supuestos!$B$2-Supuestos!$B$3-F18 | L18: =K18/J18 | M18: =ROUNDUP(MAX(2*J18*0.92,(2*E18+Supuestos!$B$6+Supuestos!$B$3+8)/(1-Supuestos!$B$2)),0)-0.01 | N18: =M18-M18*Supuestos!$B$2-Supuestos!$B$3-2*E18-Supuestos!$B$6 | O18: Sin precio de mercado: precio objetivo | P18: Sin datos de mercado | R18: 2
A19: GE | B19: FQ18MN | D19: 78.28 | E19: =D19*(1+Supuestos!$B$4) | F19: =E19+Supuestos!$B$5 | G19: =ROUNDUP((F19+Supuestos!$B$3+Supuestos!$B$9)/(1-Supuestos!$B$2),0)-0.01 | H19: =ROUNDUP(MAX((F19+Supuestos!$B$3)/(1-Supuestos!$B$2-Supuestos!$B$8),(F19+Supuestos!$B$3+Supuestos!$B$7)/(1-Supuestos!$B$2)),0)-0.01 | J19: 116.99 | K19: =J19-J19*Supuestos!$B$2-Supuestos!$B$3-F19 | L19: =K19/J19 | M19: =ROUNDUP(MAX(2*J19*0.92,(2*E19+Supuestos!$B$6+Supuestos!$B$3+8)/(1-Supuestos!$B$2)),0)-0.01 | N19: =M19-M19*Supuestos!$B$2-Supuestos!$B$3-2*E19-Supuestos!$B$6 | O19: Sin precio de mercado: precio objetivo | P19: Sin datos de mercado | R19: 2
A20: GE | B20: FQK1K | D20: 36 | E20: =D20*(1+Supuestos!$B$4) | F20: =E20+Supuestos!$B$5 | G20: =ROUNDUP((F20+Supuestos!$B$3+Supuestos!$B$9)/(1-Supuestos!$B$2),0)-0.01 | H20: =ROUNDUP(MAX((F20+Supuestos!$B$3)/(1-Supuestos!$B$2-Supuestos!$B$8),(F20+Supuestos!$B$3+Supuestos!$B$7)/(1-Supuestos!$B$2)),0)-0.01 | J20: 58.99 | K20: =J20-J20*Supuestos!$B$2-Supuestos!$B$3-F20 | L20: =K20/J20 | M20: =ROUNDUP(MAX(2*J20*0.92,(2*E20+Supuestos!$B$6+Supuestos!$B$3+8)/(1-Supuestos!$B$2)),0)-0.01 | N20: =M20-M20*Supuestos!$B$2-Supuestos!$B$3-2*E20-Supuestos!$B$6 | O20: Sin precio de mercado: precio objetivo | P20: Sin datos de mercado | R20: 2
A21: GE | B21: FQK2J | D21: 59.15 | E21: =D21*(1+Supuestos!$B$4) | F21: =E21+Supuestos!$B$5 | G21: =ROUNDUP((F21+Supuestos!$B$3+Supuestos!$B$9)/(1-Supuestos!$B$2),0)-0.01 | H21: =ROUNDUP(MAX((F21+Supuestos!$B$3)/(1-Supuestos!$B$2-Supuestos!$B$8),(F21+Supuestos!$B$3+Supuestos!$B$7)/(1-Supuestos!$B$2)),0)-0.01 | J21: 90.99 | K21: =J21-J21*Supuestos!$B$2-Supuestos!$B$3-F21 | L21: =K21/J21 | M21: =ROUNDUP(MAX(2*J21*0.92,(2*E21+Supuestos!$B$6+Supuestos!$B$3+8)/(1-Supuestos!$B$2)),0)-0.01 | N21: =M21-M21*Supuestos!$B$2-Supuestos!$B$3-2*E21-Supuestos!$B$6 | O21: Sin precio de mercado: precio objetivo | P21: Sin datos de mercado | R21: 2
A22: GE | B22: FQROPF | D22: 60.91 | E22: =D22*(1+Supuestos!$B$4) | F22: =E22+Supuestos!$B$5 | G22: =ROUNDUP((F22+Supuestos!$B$3+Supuestos!$B$9)/(1-Supuestos!$B$2),0)-0.01 | H22: =ROUNDUP(MAX((F22+Supuestos!$B$3)/(1-Supuestos!$B$2-Supuestos!$B$8),(F22+Supuestos!$B$3+Supuestos!$B$7)/(1-Supuestos!$B$2)),0)-0.01 | J22: 92.99 | K22: =J22-J22*Supuestos!$B$2-Supuestos!$B$3-F22 | L22: =K22/J22 | M22: =ROUNDUP(MAX(2*J22*0.92,(2*E22+Supuestos!$B$6+Supuestos!$B$3+8)/(1-Supuestos!$B$2)),0)-0.01 | N22: =M22-M22*Supuestos!$B$2-Supuestos!$B$3-2*E22-Supuestos!$B$6 | O22: Sin precio de mercado: precio objetivo | P22: Sin datos de mercado | R22: 1
A23: GE | B23: FQSVN | D23: 43.4 | E23: =D23*(1+Supuestos!$B$4) | F23: =E23+Supuestos!$B$5 | G23: =ROUNDUP((F23+Supuestos!$B$3+Supuestos!$B$9)/(1-Supuestos!$B$2),0)-0.01 | H23: =ROUNDUP(MAX((F23+Supuestos!$B$3)/(1-Supuestos!$B$2-Supuestos!$B$8),(F23+Supuestos!$B$3+Supuestos!$B$7)/(1-Supuestos!$B$2)),0)-0.01 | J23: 68.99 | K23: =J23-J23*Supuestos!$B$2-Supuestos!$B$3-F23 | L23: =K23/J23 | M23: =ROUNDUP(MAX(2*J23*0.92,(2*E23+Supuestos!$B$6+Supuestos!$B$3+8)/(1-Supuestos!$B$2)),0)-0.01 | N23: =M23-M23*Supuestos!$B$2-Supuestos!$B$3-2*E23-Supuestos!$B$6 | O23: Sin precio de mercado: precio objetivo | P23: Sin datos de mercado | R23: 2
A24: GE | B24: FTHLM | D24: 60.46 | E24: =D24*(1+Supuestos!$B$4) | F24: =E24+Supuestos!$B$5 | G24: =ROUNDUP((F24+Supuestos!$B$3+Supuestos!$B$9)/(1-Supuestos!$B$2),0)-0.01 | H24: =ROUNDUP(MAX((F24+Supuestos!$B$3)/(1-Supuestos!$B$2-Supuestos!$B$8),(F24+Supuestos!$B$3+Supuestos!$B$7)/(1-Supuestos!$B$2)),0)-0.01 | J24: 91.99 | K24: =J24-J24*Supuestos!$B$2-Supuestos!$B$3-F24 | L24: =K24/J24 | M24: =ROUNDUP(MAX(2*J24*0.92,(2*E24+Supuestos!$B$6+Supuestos!$B$3+8)/(1-Supuestos!$B$2)),0)-0.01 | N24: =M24-M24*Supuestos!$B$2-Supuestos!$B$3-2*E24-Supuestos!$B$6 | O24: Sin precio de mercado: precio objetivo | P24: Sin datos de mercado | R24: 2
A25: GE | B25: FTHTM | D25: 30.97 | E25: =D25*(1+Supuestos!$B$4) | F25: =E25+Supuestos!$B$5 | G25: =ROUNDUP((F25+Supuestos!$B$3+Supuestos!$B$9)/(1-Supuestos!$B$2),0)-0.01 | H25: =ROUNDUP(MAX((F25+Supuestos!$B$3)/(1-Supuestos!$B$2-Supuestos!$B$8),(F25+Supuestos!$B$3+Supuestos!$B$7)/(1-Supuestos!$B$2)),0)-0.01 | J25: 51.99 | K25: =J25-J25*Supuestos!$B$2-Supuestos!$B$3-F25 | L25: =K25/J25 | M25: =ROUNDUP(MAX(2*J25*0.92,(2*E25+Supuestos!$B$6+Supuestos!$B$3+8)/(1-Supuestos!$B$2)),0)-0.01 | N25: =M25-M25*Supuestos!$B$2-Supuestos!$B$3-2*E25-Supuestos!$B$6 | O25: Sin precio de mercado: precio objetivo | P25: Sin datos de mercado | R25: 2
A26: GE | B26: FX12M | D26: 60.46 | E26: =D26*(1+Supuestos!$B$4) | F26: =E26+Supuestos!$B$5 | G26: =ROUNDUP((F26+Supuestos!$B$3+Supuestos!$B$9)/(1-Supuestos!$B$2),0)-0.01 | H26: =ROUNDUP(MAX((F26+Supuestos!$B$3)/(1-Supuestos!$B$2-Supuestos!$B$8),(F26+Supuestos!$B$3+Supuestos!$B$7)/(1-Supuestos!$B$2)),0)-0.01 | J26: 91.99 | K26: =J26-J26*Supuestos!$B$2-Supuestos!$B$3-F26 | L26: =K26/J26 | M26: =ROUNDUP(MAX(2*J26*0.92,(2*E26+Supuestos!$B$6+Supuestos!$B$3+8)/(1-Supuestos!$B$2)),0)-0.01 | N26: =M26-M26*Supuestos!$B$2-Supuestos!$B$3-2*E26-Supuestos!$B$6 | O26: Sin precio de mercado: precio objetivo | P26: Sin datos de mercado | R26: 2
A27: GE | B27: FXHSC | D27: 20.31 | E27: =D27*(1+Supuestos!$B$4) | F27: =E27+Supuestos!$B$5 | G27: =ROUNDUP((F27+Supuestos!$B$3+Supuestos!$B$9)/(1-Supuestos!$B$2),0)-0.01 | H27: =ROUNDUP(MAX((F27+Supuestos!$B$3)/(1-Supuestos!$B$2-Supuestos!$B$8),(F27+Supuestos!$B$3+Supuestos!$B$7)/(1-Supuestos!$B$2)),0)-0.01 | J27: 37.99 | K27: =J27-J27*Supuestos!$B$2-Supuestos!$B$3-F27 | L27: =K27/J27 | M27: =ROUNDUP(MAX(2*J27*0.92,(2*E27+Supuestos!$B$6+Supuestos!$B$3+8)/(1-Supuestos!$B$2)),0)-0.01 | N27: =M27-M27*Supuestos!$B$2-Supuestos!$B$3-2*E27-Supuestos!$B$6 | O27: Sin precio de mercado: precio objetivo | P27: Sin datos de mercado | R27: 1
A28: GE | B28: FXHTC | D28: 33.09 | E28: =D28*(1+Supuestos!$B$4) | F28: =E28+Supuestos!$B$5 | G28: =ROUNDUP((F28+Supuestos!$B$3+Supuestos!$B$9)/(1-Supuestos!$B$2),0)-0.01 | H28: =ROUNDUP(MAX((F28+Supuestos!$B$3)/(1-Supuestos!$B$2-Supuestos!$B$8),(F28+Supuestos!$B$3+Supuestos!$B$7)/(1-Supuestos!$B$2)),0)-0.01 | J28: 54.99 | K28: =J28-J28*Supuestos!$B$2-Supuestos!$B$3-F28 | L28: =K28/J28 | M28: =ROUNDUP(MAX(2*J28*0.92,(2*E28+Supuestos!$B$6+Supuestos!$B$3+8)/(1-Supuestos!$B$2)),0)-0.01 | N28: =M28-M28*Supuestos!$B$2-Supuestos!$B$3-2*E28-Supuestos!$B$6 | O28: Sin precio de mercado: precio objetivo | P28: Sin datos de mercado | R28: 2
... A50: Frigidaire | B50: PAULTRA2 | D50: 14 | E50: =D50*(1+Supuestos!$B$4) | F50: =E50+Supuestos!$B$5 | G50: =ROUNDUP((F50+Supuestos!$B$3+Supuestos!$B$9)/(1-Supuestos!$B$2),0)-0.01 | H50: =ROUNDUP(MAX((F50+Supuestos!$B$3)/(1-Supuestos!$B$2-Supuestos!$B$8),(F50+Supuestos!$B$3+Supuestos!$B$7)/(1-Supuestos!$B$2)),0)-0.01 | J50: 30.99 | K50: =J50-J50*Supuestos!$B$2-Supuestos!$B$3-F50 | L50: =K50/J50 | M50: =ROUNDUP(MAX(2*J50*0.92,(2*E50+Supuestos!$B$6+Supuestos!$B$3+8)/(1-Supuestos!$B$2)),0)-0.01 | N50: =M50-M50*Supuestos!$B$2-Supuestos!$B$3-2*E50-Supuestos!$B$6 | O50: Sin precio de mercado: precio objetivo | P50: Sin datos de mercado | R50: 6
A51: Frigidaire | B51: PAULTRA2PK | D51: 22.47 | E51: =D51*(1+Supuestos!$B$4) | F51: =E51+Supuestos!$B$5 | G51: =ROUNDUP((F51+Supuestos!$B$3+Supuestos!$B$9)/(1-Supuestos!$B$2),0)-0.01 | H51: =ROUNDUP(MAX((F51+Supuestos!$B$3)/(1-Supuestos!$B$2-Supuestos!$B$8),(F51+Supuestos!$B$3+Supuestos!$B$7)/(1-Supuestos!$B$2)),0)-0.01 | J51: 40.99 | K51: =J51-J51*Supuestos!$B$2-Supuestos!$B$3-F51 | L51: =K51/J51 | M51: =ROUNDUP(MAX(2*J51*0.92,(2*E51+Supuestos!$B$6+Supuestos!$B$3+8)/(1-Supuestos!$B$2)),0)-0.01 | N51: =M51-M51*Supuestos!$B$2-Supuestos!$B$3-2*E51-Supuestos!$B$6 | O51: Sin precio de mercado: precio objetivo | P51: Sin datos de mercado
A52: Frigidaire | B52: PAULTRA4PK | D52: 35.67 | E52: =D52*(1+Supuestos!$B$4) | F52: =E52+Supuestos!$B$5 | G52: =ROUNDUP((F52+Supuestos!$B$3+Supuestos!$B$9)/(1-Supuestos!$B$2),0)-0.01 | H52: =ROUNDUP(MAX((F52+Supuestos!$B$3)/(1-Supuestos!$B$2-Supuestos!$B$8),(F52+Supuestos!$B$3+Supuestos!$B$7)/(1-Supuestos!$B$2)),0)-0.01 | J52: 58.99 | K52: =J52-J52*Supuestos!$B$2-Supuestos!$B$3-F52 | L52: =K52/J52 | M52: =ROUNDUP(MAX(2*J52*0.92,(2*E52+Supuestos!$B$6+Supuestos!$B$3+8)/(1-Supuestos!$B$2)),0)-0.01 | N52: =M52-M52*Supuestos!$B$2-Supuestos!$B$3-2*E52-Supuestos!$B$6 | O52: Sin precio de mercado: precio objetivo | P52: Sin datos de mercado
A53: Frigidaire | B53: PAULTRAII2PK | D53: 22.48 | E53: =D53*(1+Supuestos!$B$4) | F53: =E53+Supuestos!$B$5 | G53: =ROUNDUP((F53+Supuestos!$B$3+Supuestos!$B$9)/(1-Supuestos!$B$2),0)-0.01 | H53: =ROUNDUP(MAX((F53+Supuestos!$B$3)/(1-Supuestos!$B$2-Supuestos!$B$8),(F53+Supuestos!$B$3+Supuestos!$B$7)/(1-Supuestos!$B$2)),0)-0.01 | J53: 40.99 | K53: =J53-J53*Supuestos!$B$2-Supuestos!$B$3-F53 | L53: =K53/J53 | M53: =ROUNDUP(MAX(2*J53*0.92,(2*E53+Supuestos!$B$6+Supuestos!$B$3+8)/(1-Supuestos!$B$2)),0)-0.01 | N53: =M53-M53*Supuestos!$B$2-Supuestos!$B$3-2*E53-Supuestos!$B$6 | O53: Sin precio de mercado: precio objetivo | P53: Sin datos de mercado
A54: Frigidaire | B54: AFCB | D54: 12.65 | E54: =D54*(1+Supuestos!$B$4) | F54: =E54+Supuestos!$B$5 | G54: =ROUNDUP((F54+Supuestos!$B$3+Supuestos!$B$9)/(1-Supuestos!$B$2),0)-0.01 | H54: =ROUNDUP(MAX((F54+Supuestos!$B$3)/(1-Supuestos!$B$2-Supuestos!$B$8),(F54+Supuestos!$B$3+Supuestos!$B$7)/(1-Supuestos!$B$2)),0)-0.01 | J54: 29.99 | K54: =J54-J54*Supuestos!$B$2-Supuestos!$B$3-F54 | L54: =K54/J54 | M54: =ROUNDUP(MAX(2*J54*0.92,(2*E54+Supuestos!$B$6+Supuestos!$B$3+8)/(1-Supuestos!$B$2)),0)-0.01 | N54: =M54-M54*Supuestos!$B$2-Supuestos!$B$3-2*E54-Supuestos!$B$6 | O54: Sin precio de mercado: precio objetivo | P54: Sin datos de mercado
A55: Frigidaire | B55: TMFRGPAAF1KT | D55: 16.23 | E55: =D55*(1+Supuestos!$B$4) | F55: =E55+Supuestos!$B$5 | G55: =ROUNDUP((F55+Supuestos!$B$3+Supuestos!$B$9)/(1-Supuestos!$B$2),0)-0.01 | H55: =ROUNDUP(MAX((F55+Supuestos!$B$3)/(1-Supuestos!$B$2-Supuestos!$B$8),(F55+Supuestos!$B$3+Supuestos!$B$7)/(1-Supuestos!$B$2)),0)-0.01 | J55: 33.99 | K55: =J55-J55*Supuestos!$B$2-Supuestos!$B$3-F55 | L55: =K55/J55 | M55: =ROUNDUP(MAX(2*J55*0.92,(2*E55+Supuestos!$B$6+Supuestos!$B$3+8)/(1-Supuestos!$B$2)),0)-0.01 | N55: =M55-M55*Supuestos!$B$2-Supuestos!$B$3-2*E55-Supuestos!$B$6 | O55: Sin precio de mercado: precio objetivo | P55: Sin datos de mercado
A56: Frigidaire | B56: FRGPAAF1 | D56: 14.68 | E56: =D56*(1+Supuestos!$B$4) | F56: =E56+Supuestos!$B$5 | G56: =ROUNDUP((F56+Supuestos!$B$3+Supuestos!$B$9)/(1-Supuestos!$B$2),0)-0.01 | H56: =ROUNDUP(MAX((F56+Supuestos!$B$3)/(1-Supuestos!$B$2-Supuestos!$B$8),(F56+Supuestos!$B$3+Supuestos!$B$7)/(1-Supuestos!$B$2)),0)-0.01 | J56: 31.99 | K56: =J56-J56*Supuestos!$B$2-Supuestos!$B$3-F56 | L56: =K56/J56 | M56: =ROUNDUP(MAX(2*J56*0.92,(2*E56+Supuestos!$B$6+Supuestos!$B$3+8)/(1-Supuestos!$B$2)),0)-0.01 | N56: =M56-M56*Supuestos!$B$2-Supuestos!$B$3-2*E56-Supuestos!$B$6 | O56: Sin precio de mercado: precio objetivo | P56: Sin datos de mercado | R56: 6
A57: Frigidaire | B57: FRGPAAF2 | D57: 15.02 | E57: =D57*(1+Supuestos!$B$4) | F57: =E57+Supuestos!$B$5 | G57: =ROUNDUP((F57+Supuestos!$B$3+Supuestos!$B$9)/(1-Supuestos!$B$2),0)-0.01 | H57: =ROUNDUP(MAX((F57+Supuestos!$B$3)/(1-Supuestos!$B$2-Supuestos!$B$8),(F57+Supuestos!$B$3+Supuestos!$B$7)/(1-Supuestos!$B$2)),0)-0.01 | J57: 31.99 | K57: =J57-J57*Supuestos!$B$2-Supuestos!$B$3-F57 | L57: =K57/J57 | M57: =ROUNDUP(MAX(2*J57*0.92,(2*E57+Supuestos!$B$6+Supuestos!$B$3+8)/(1-Supuestos!$B$2)),0)-0.01 | N57: =M57-M57*Supuestos!$B$2-Supuestos!$B$3-2*E57-Supuestos!$B$6 | O57: Sin precio de mercado: precio objetivo | P57: Sin datos de mercado | R57: 6
A58: Frigidaire | B58: FRGPAAF12PK | D58: 29.35 | E58: =D58*(1+Supuestos!$B$4) | F58: =E58+Supuestos!$B$5 | G58: =ROUNDUP((F58+Supuestos!$B$3+Supuestos!$B$9)/(1-Supuestos!$B$2),0)-0.01 | H58: =ROUNDUP(MAX((F58+Supuestos!$B$3)/(1-Supuestos!$B$2-Supuestos!$B$8),(F58+Supuestos!$B$3+Supuestos!$B$7)/(1-Supuestos!$B$2)),0)-0.01 | J58: 49.99 | K58: =J58-J58*Supuestos!$B$2-Supuestos!$B$3-F58 | L58: =K58/J58 | M58: =ROUNDUP(MAX(2*J58*0.92,(2*E58+Supuestos!$B$6+Supuestos!$B$3+8)/(1-Supuestos!$B$2)),0)-0.01 | N58: =M58-M58*Supuestos!$B$2-Supuestos!$B$3-2*E58-Supuestos!$B$6 | O58: Sin precio de mercado: precio objetivo | P58: Sin datos de mercado
A59: Frigidaire | B59: FRGPAAF22PK | D59: 24.92 | E59: =D59*(1+Supuestos!$B$4) | F59: =E59+Supuestos!$B$5 | G59: =ROUNDUP((F59+Supuestos!$B$3+Supuestos!$B$9)/(1-Supuestos!$B$2),0)-0.01 | H59: =ROUNDUP(MAX((F59+Supuestos!$B$3)/(1-Supuestos!$B$2-Supuestos!$B$8),(F59+Supuestos!$B$3+Supuestos!$B$7)/(1-Supuestos!$B$2)),0)-0.01 | J59: 43.99 | K59: =J59-J59*Supuestos!$B$2-Supuestos!$B$3-F59 | L59: =K59/J59 | M59: =ROUNDUP(MAX(2*J59*0.92,(2*E59+Supuestos!$B$6+Supuestos!$B$3+8)/(1-Supuestos!$B$2)),0)-0.01 | N59: =M59-M59*Supuestos!$B$2-Supuestos!$B$3-2*E59-Supuestos!$B$6 | O59: Sin precio de mercado: precio objetivo | P59: Sin datos de mercado
A60: Frigidaire | B60: FRGPAAF24PK | D60: 44.3 | E60: =D60*(1+Supuestos!$B$4) | F60: =E60+Supuestos!$B$5 | G60: =ROUNDUP((F60+Supuestos!$B$3+Supuestos!$B$9)/(1-Supuestos!$B$2),0)-0.01 | H60: =ROUNDUP(MAX((F60+Supuestos!$B$3)/(1-Supuestos!$B$2-Supuestos!$B$8),(F60+Supuestos!$B$3+Supuestos!$B$7)/(1-Supuestos!$B$2)),0)-0.01 | J60: 69.99 | K60: =J60-J60*Supuestos!$B$2-Supuestos!$B$3-F60 | L60: =K60/J60 | M60: =ROUNDUP(MAX(2*J60*0.92,(2*E60+Supuestos!$B$6+Supuestos!$B$3+8)/(1-Supuestos!$B$2)),0)-0.01 | N60: =M60-M60*Supuestos!$B$2-Supuestos!$B$3-2*E60-Supuestos!$B$6 | O60: Sin precio de mercado: precio objetivo | P60: Sin datos de mercado
A61: Frigidaire | B61: FRPFUAF1 | D61: 9.59 | E61: =D61*(1+Supuestos!$B$4) | F61: =E61+Supuestos!$B$5 | G61: =ROUNDUP((F61+Supuestos!$B$3+Supuestos!$B$9)/(1-Supuestos!$B$2),0)-0.01 | H61: =ROUNDUP(MAX((F61+Supuestos!$B$3)/(1-Supuestos!$B$2-Supuestos!$B$8),(F61+Supuestos!$B$3+Supuestos!$B$7)/(1-Supuestos!$B$2)),0)-0.01 | J61: 25.99 | K61: =J61-J61*Supuestos!$B$2-Supuestos!$B$3-F61 | L61: =K61/J61 | M61: =ROUNDUP(MAX(2*J61*0.92,(2*E61+Supuestos!$B$6+Supuestos!$B$3+8)/(1-Supuestos!$B$2)),0)-0.01 | N61: =M61-M61*Supuestos!$B$2-Supuestos!$B$3-2*E61-Supuestos!$B$6 | O61: Sin precio de mercado: precio objetivo | P61: Sin datos de mercado | R61: 6
...

Sheet Supuestos
A1: Supuesto (cámbialo y la hoja se recalcula) | B1: Valor | C1: Qué es
A2: Comisión de PayPal (%) | B2: 0.054 | C2: Comisión por venta. Verifica la de tu cuenta: es una suposición conservadora para una cuenta en Colombia.
A3: Comisión fija por venta (USD) | B3: 0.3 | C3: Cargo fijo por transacción.
A4: Flete y gastos hasta tu depósito (%) | B4: 0.08 | C4: Sobre el precio del proveedor: flete, aranceles, almacenaje. Pon el real.
A5: Envío al cliente, 1 filtro (USD) | B5: 7.5 | C5: Etiqueta promedio nacional (USPS Ground Advantage, menos de 1 lb: unos $5.50 a $8.40 según la zona) + empaque. Si el precio incluye envío gratis, se suma al costo.
A6: Envío al cliente, paquete de 2 (USD) | B6: 9.5 | C6: Etiqueta + empaque.
A7: Ganancia mínima por pedido (USD) | B7: 6 | C7: Para el precio objetivo.
A8: Margen mínimo sobre el precio (%) | B8: 0.15 | C8: Para el precio objetivo.
A9: Ganancia mínima absoluta (USD) | B9: 4 | C9: Para el precio mínimo (el piso).

Sheet Cómo leer
A1: Cómo se calcula el precio
A2: 1. Costo puesto en depósito = precio del proveedor + flete y gastos (%).
A3: 2. Costo + envío al cliente = lo anterior + etiqueta y empaque. El precio de venta incluye envío (envío gratis para el cliente).
A4: 3. Precio mínimo: el menor precio con el que ganas el «piso» (USD) después de la comisión de PayPal.
A5: 4. Precio objetivo: el menor precio que deja al menos la ganancia mínima y el margen mínimo.
A6: 5. Precio de la calle: lo que he visto que cobran otras tiendas por el filtro original (capturas de búsqueda, pueden haber cambiado: verifícalos en Amazon, Walmart y Home Depot antes de publicar).
A7: 6. PRECIO DE VENTA: el objetivo si es competitivo; si no, se iguala al mercado siempre que quede ganancia; si el mercado está casi al precio de costo, no conviene venderlo suelto.
A8: 7. Paquete de 2: descuento de 8 % (mínimo $8 de ganancia): invita a comprar de a 2 y diluye el envío.
A10: Aviso: los precios de mercado son capturas de internet de 2025–2026; cambian a diario. Los costos de flete, aranceles y la comisión de PayPal son supuestos tuyos que debes ajustar en la hoja «Supuestos».
